Workbook
Name List1: #REF!
Name List10: #REF!
Name List11: #REF!
Name List12: #REF!
Name List13: #REF!
Name List14: #REF!
Name List15: #REF!
Name List16: #REF!
Name List17: #REF!
Name List18: #REF!
Name List19: #REF!
Name List2: #REF!
Name List20: #REF!
Name List21: #REF!
Name List3: #REF!
Name List3b: #REF!
Name List4: #REF!
Name List5: #REF!
Name List7: #REF!
Name List8: #REF!
Name List9: #REF!
Name Plantas: [1]BACK!$J$3:$J$7
Name Slicer_DPTO: #N/A
Name table1: #REF!
Name Table2: '[2]C2018 PROD Volumes Planned'!$B$2:$S$311

Sheet Sheet1
A1: DPTO | B1: MEDIO AMBIENTE
A3: Etiquetas de fila | B3: Count of SHARP
A4: CHAVOS AMBIENTALES | B4: 4
A5: ROBERTO CARLOS SANCHEZ DE SANTIAGO | B5: 4
A6: GERENTES DE HIERRO | B6: 6
A7: EDGAR OSWALDO MARTINEZ HUITRADO | B7: 6
A8: LOS ESPECIALISTAS | B8: 4
A9: NANCY ERENDIRA TEJEDOR SANTOS | B9: 4
A10: LOS PUMAS | B10: 4
A11: ALEJANDRO SALCEDO BRAVO | B11: 4
A12: LAS ESTRELLAS | B12: 7
A13: ISAI FLORES ORTIZ | B13: 7
A14: Grand Total | B14: 25

Sheet ZACATECAS
