Workbook

Sheet RESUMEN
A1: #VALUE! | B1: Resumen Elaboración
C2: NIVEL DE L'S
A3: POSICIÓN SKAP | B3: EQUIPO | C3: L6 | D3: L7 | E3: L8
A4: Operador de Materias Primas 2.0 | B4: MANEJO DE MATERIA PRIMA | C4: ='L6 Elaboración'!C3 -> 0 | D4: ='L7 Elaboración'!C3 -> 0 | E4: ='L8 Elaboración'!C3 -> 0
A5: Operador de Molienda 2.0 | B5: MOLIENDA | C5: ='L6 Elaboración'!C13 -> 0 | D5: ='L7 Elaboración'!C14 -> 0 | E5: ='L8 Elaboración'!C10 -> 0
A6: Operador de Maceración 2.0 | B6: MACERACIÓN | C6: ='L6 Elaboración'!C23 -> 0 | D6: ='L7 Elaboración'!C26 -> 0 | E6: ='L8 Elaboración'!C16 -> 0
A7: Operador de Filtración de Mosto 2.0 | B7: FILTRO DE MOSTO | C7: ='L6 Elaboración'!C31 -> 0 | D7: ='L7 Elaboración'!C37 -> 0 | E7: ='L8 Elaboración'!C25 -> 0
A8: Operador de Cocimiento 2.0 | B8: SALA DE COCIMIENTO | C8: ='L6 Elaboración'!C44 -> 0 | D8: ='L7 Elaboración'!C49 -> 0 | E8: ='L8 Elaboración'!C33 -> 0
A9: Operador de Fermentación 2.0 | B9: SALA DE FERMENTACIÓN | C9: ='L6 Elaboración'!C53 -> 0 | D9: ='L7 Elaboración'!C60 -> 0 | E9: ='L8 Elaboración'!C42 -> 0
A10: Operador de Filtración de Cerveza 2.0 | B10: SALA DE FILTROS | C10: ='L6 Elaboración'!C63 -> 0 | D10: ='L7 Elaboración'!C74 -> 0 | E10: ='L8 Elaboración'!C50 -> 0
A11: Operador de BBT 2.0 | B11: SALA BBT | C11: ='L6 Elaboración'!C71 -> 0 | D11: ='L7 Elaboración'!C85 -> 0 | E11: ='L8 Elaboración'!C58 -> 0

Sheet L6 Elaboración
A1: #VALUE! | B1: Guía Técnica L6 Elaboración
A2: INSTRUCCIONES: 1. Aplicable a operadores, técnicos mecánicos y PTE en el/los proceso(s) que corresponda 2. Seleccionar las casillas de las habilidades con las que ya cuenta la persona evaluada 3. Dejar vacías las casillas de las habilidades que aún no están desarrolladas en la persona evaluada y registrar plan de acción en "Plan de Cierre de Brechas" 4. No están permitido NA sin previa validación de Director Zonal de Mantenimiento | C2: ="COMPETENCIAS [X] Competente [ ] No competente "&IF(C4>=80%,"≧80% COMPETENTE","< 80% NO COMPETENTE") -> COMPETENCIAS [X] Competente [ ] No competente ≧80% COMPETENTE
B3: MANEJO DE MATERIA PRIMA | C3: =IFERROR(COUNTIF(C4:C12,TRUE)/COUNTA(B4:B12),0) -> 0 | D3: Método de validación sugerido | E3: ='L7 Elaboración'!E3 -> Herramientas / referencia | F3: ='L7 Elaboración'!F3 -> Comentarios / plan de acción
B4: Comprende el funcionamiento de los diferentes equipos que forman el sistema de almacenamiento, transporte y limpieza de materia prima como: Silos, transportadores, elevadores, rotoesclusas, limpiadoras de grano, imanes, filtros de polvo, básculas y dosificadores. | C4: FALSE | D4: Entrevista técnica guiada + identificación física de equipos/componentes en campo. | E4: Checklist de transporte/aspiración, manómetro/dP, tacómetro y registros PM
B5: Comprende y explica las variables críticas de seguridad en el manejo de polvo y conoce los controles necesarios en los sistemas de transporte de materias primas y los monitorea de manera rutinaria (Rutinas PM). | C5: FALSE | D5: Entrevista técnica guiada + identificación física de equipos/componentes en campo. | E5: Checklist de transporte/aspiración, manómetro/dP, tacómetro y registros PM
B6: Reconoce riesgos críticos asociados al manejo de materia prima: Polvo combustible, atrapamiento, caída de material, contaminación cruzada, derrames y limpieza deficiente del área. | C6: FALSE | D6: Caso de desviación + recorrido en campo + preguntas de causa/impacto/escalamiento. | E6: Checklist de transporte/aspiración, manómetro/dP, tacómetro y registros PM
B7: Identifica sensores y protecciones del sistema de materia prima: Detección de nivel alto/bajo, velocidad, desvío de banda, detección de atasco y presión diferencial en filtros de mangas. Es capaz de identificar alarmas en el sistema SCADA/HMI local sugiriendo posibles soluciones al equipo de mantenimiento. | C7: FALSE | D7: Prueba práctica en Scada/campo con checklist y explicación de criterio de aceptación. | E7: HMI/SCADA, históricos de tendencia, alarmas y SOP de respuesta; Checklist de transporte/aspiración, manómetro/dP, tacómetro y registros PM
B8: Explica la función del sistema de aspiración y filtración de polvo, relacionando presión diferencial, limpieza por pulsos, fugas de polvo y condición de mangas con estabilidad operativa. | C8: FALSE | D8: Entrevista técnica guiada + identificación física de equipos/componentes en campo. | E8: Checklist de transporte/aspiración, manómetro/dP, tacómetro y registros PM
B9: Relaciona capacidad de transporte, velocidad, amperaje y condición mecánica con posibles sobrecargas, desalineación, rotura de cangilones, atascos o pérdida de flujo. | C9: FALSE | D9: Entrevista técnica guiada + identificación física de equipos/componentes en campo. | E9: Checklist de transporte/aspiración, manómetro/dP, tacómetro y registros PM; Checklist de bombas/sellos, alineador, comparador, vibrómetro y manual OEM
B10: Conoce y está en capacidad de realizar la medición en el flujo de aspiración y regularlo de ser necesario. Identifica la presión de trabajo de las mangas y conoce los límites máximos para asegurar un buen funcionamiento (7 a 15 mbar). | C10: FALSE | D10: Entrevista técnica guiada + identificación física de equipos/componentes en campo. | E10: Checklist de transporte/aspiración, manómetro/dP, tacómetro y registros PM
B11: Reconoce condiciones anormales en campo: Ruido excesivo, alta vibración, calentamiento, polvo excesivo, derrames, caída de caudal, activación de alarmas o consumo eléctrico fuera de tendencia. Genera avisos de mantenimiento con el detalle requerido y completo. | C11: FALSE | D11: Caso de desviación + recorrido en campo + preguntas de causa/impacto/escalamiento. | E11: HMI/SCADA, históricos de tendencia, alarmas y SOP de respuesta; Checklist de transporte/aspiración, manómetro/dP, tacómetro y registros PM; P&ID de vapor/condensado, termografía, manómetros y registros de rampa térmica
B12: Valida que los ajustes realizados al sistema, trabajen acorde a los requerimientos de proceso. | C12: FALSE | D12: Entrevista técnica guiada + validación con resultados en receta. | E12: Recorrido en campo, HMI/SCADA, SOP del área y checklist de operación
B13: MOLIENDA | C13: =IFERROR(COUNTIF(C14:C22,TRUE)/COUNTA(B14:B22),0) -> 0 | D13: Método de validación sugerido | E13: ='L7 Elaboración'!E3 -> Herramientas / referencia | F13: ='L7 Elaboración'!F3 -> Comentarios / plan de acción
B14: Comprende el funcionamiento de los componentes principales del sistema de molienda: Alimentador, imanes, acondicionador/humectación, rodillos o martillos, cribas, compuertas, aspiración y descarga. | C14: FALSE | D14: Entrevista técnica guiada + identificación física de equipos/componentes en campo. | E14: Checklist de transporte/aspiración, manómetro/dP, tacómetro y registros PM; Tamices/granulometría, galgas, amperímetro, manual OEM y checklist de molino; Matriz CIP, registro de conductividad/temperatura/tiempo, ATP/micro si aplica
B15: Explica el objetivo técnico de la molienda y cómo impacta en la extracción, conversión, filtrabilidad y rendimiento de sala. | C15: FALSE | D15: Entrevista técnica guiada + identificación física de equipos/componentes en campo. | E15: Tamices/granulometría, galgas, amperímetro, manual OEM y checklist de molino
B16: Interpreta variables operativas de molienda: Distancia entre rodillos, velocidad de transporte, caudal de alimentación, húmedad de acondicionamiento, amperaje en molino, aspiración y temperatura. (Si aplica). | C16: FALSE | D16: Análisis de tendencia/histórico + entrevista técnica + validación en Scada. | E16: Checklist de transporte/aspiración, manómetro/dP, tacómetro y registros PM; Tamices/granulometría, galgas, amperímetro, manual OEM y checklist de molino
B17: Reconoce síntomas de molienda fuera de condición: Bajo o alto porcentaje de finos, grano entero, cáscara destruida, granulometría inestable, baja velocidad, polvo excesivo o incremento de tiempo de molienda o consumo de energía. | C17: FALSE | D17: Caso de desviación + recorrido en campo + preguntas de causa/impacto/escalamiento. | E17: Checklist de transporte/aspiración, manómetro/dP, tacómetro y registros PM; Tamices/granulometría, galgas, amperímetro, manual OEM y checklist de molino
B18: Verifica protecciones y controles de seguridad del sistema: Imanes, detectores metálicos, puertas enclavadas, paros de emergencia, filtros de polvo y secuencia de arranque/parada. Es capaz de identificar alarmas en el sistema SCADA/HMI local y genera avisos de mantenimiento sugiriendo posibles soluciones al equipo de mantenimiento. | C18: FALSE | D18: Prueba práctica en Scada/campo con checklist y explicación de criterio de aceptación. | E18: HMI/SCADA, históricos de tendencia, alarmas y SOP de respuesta; P&ID, matriz de válvulas, secuencia de operación/CIP y checklist de ruta; Checklist de transporte/aspiración, manómetro/dP, tacómetro y registros PM
B19: Relaciona el desgaste de rodillos, martillos, cribas, rodamientos o placas de impacto con variables de monitoreo como vibración, ruido, sobrecorriente, baja capacidad y desviación de granulometría. | C19: FALSE | D19: Caso de desviación + recorrido en campo + preguntas de causa/impacto/escalamiento. | E19: Tamices/granulometría, galgas, amperímetro, manual OEM y checklist de molino; Analizador de vibraciones, espectros/tendencias, rutas CBM y límites de severidad
B20: Conoce y está en capacidad de identificar en molino de martillos desgaste de martillos y chapa perforada. En molino de rodillos la medición de apertura de rodillos y su regulación de ser necesario. | C20: FALSE | D20: Entrevista técnica guiada + identificación física de equipos/componentes en campo. | E20: Tamices/granulometría, galgas, amperímetro, manual OEM y checklist de molino
B21: Conoce y está en capacidad de realizar la regulación de velocidad en transportes de grano del sistema de molienda y alimentación al molino. Realiza la regulación de la humectación del grano en molienda acondicionada, diagnóstico y ceonoce los parametros de trabajo de la bomba de descargue de masa en molienda húmeda. | C21: FALSE | D21: Entrevista técnica guiada + identificación física de equipos/componentes en campo. | E21: Checklist de transporte/aspiración, manómetro/dP, tacómetro y registros PM; Tamices/granulometría, galgas, amperímetro, manual OEM y checklist de molino; Checklist de bombas/sellos, alineador, comparador, vibrómetro y manual OEM
B22: Valida que los ajustes realizados trabajen de acuerdo a lo requerido por el proceso, monitoreando condición de la molienda mediante muestra representativa, ausencia de cuerpos extraños, estabilidad del equipo y cumplimiento de parámetros de receta. | C22: FALSE | D22: Entrevista técnica guiada + validación con resultados en receta. | E22: Tamices/granulometría, galgas, amperímetro, manual OEM y checklist de molino
B23: MACERACIÓN | C23: =IFERROR(COUNTIF(C24:C30,TRUE)/COUNTA(B24:B30),0) -> 0 | D23: Método de validación sugerido | E23: ='L7 Elaboración'!E3 -> Herramientas / referencia | F23: ='L7 Elaboración'!F3 -> Comentarios / plan de acción
B24: Comprende el funcionamiento de los diferentes equipos del sistema de maceración como: Macerador, Pre-macerador, agitadores, bombas de macerado, válvulas, líneas de transferencia, sistema de calentamiento, instrumentación y circuitos CIP asociados. | C24: FALSE | D24: Entrevista técnica guiada + identificación física de equipos/componentes en campo. | E24: P&ID, matriz de válvulas, secuencia de operación/CIP y checklist de ruta; P&ID de vapor/condensado, termografía, manómetros y registros de rampa térmica; Matriz CIP, registro de conductividad/temperatura/tiempo, ATP/micro si aplica
B25: Reconoce desviaciones típicas: Rampa térmica lenta, mezcla heterogénea, formación de grumos y las relaciona con alto amperaje de agitador, cavitación de bomba o error de secuencia/receta. | C25: FALSE | D25: Caso de desviación + recorrido en campo + preguntas de causa/impacto/escalamiento. | E25: P&ID, matriz de válvulas, secuencia de operación/CIP y checklist de ruta; Checklist de bombas/sellos, alineador, comparador, vibrómetro y manual OEM
B26: Reconoce instrumentación crítica de maceración: Temperatura, nivel, caudal, presión y pH, explicando el impacto de una medición errónea sobre receta, calidad y seguridad. Es capaz de identificar en el SCADA cuando se presenta una falla en el instrumento de medición y genera avisos de mantenimiento. | C26: FALSE | D26: Prueba práctica en Scada/campo con checklist y explicación de criterio de aceptación. | E26: HMI/SCADA, históricos de tendencia, alarmas y SOP de respuesta
B27: Relaciona fallas de agitadores, bombas, válvulas o sensores con baja conversión, variación de extracto, aumento de viscosidad, mala homogeneidad y problemas de filtrabilidad. | C27: FALSE | D27: Entrevista técnica guiada + identificación física de equipos/componentes en campo. | E27: P&ID, matriz de válvulas, secuencia de operación/CIP y checklist de ruta; Checklist de bombas/sellos, alineador, comparador, vibrómetro y manual OEM
B28: Verifica condición operaciónal del sistema de calentamiento: válvulas de vapor, trampas, retorno de condensado, camisa/calandria, control de temperatura y ausencia de golpes de ariete. | C28: FALSE | D28: Prueba práctica en Scada/campo con checklist y explicación de criterio de aceptación. | E28: P&ID, matriz de válvulas, secuencia de operación/CIP y checklist de ruta; P&ID de vapor/condensado, termografía, manómetros y registros de rampa térmica
B29: Conoce y hace uso del histórico de gráficas, protocolo de pasos, reporte de alarmas del sistema SCADA/HMI para identificar fallas o desviaciones en el comportamiento de los principales equipos de la sala de maceración. | C29: FALSE | D29: Análisis de tendencia/histórico + entrevista técnica + validación en HMI. | E29: HMI/SCADA, históricos de tendencia, alarmas y SOP de respuesta; Matriz CIP, registro de conductividad/temperatura/tiempo, ATP/micro si aplica
B30: Valida la transferencia hacia filtración confirmando volumen, temperatura, homogeneidad, secuencia correcta, ausencia de alarmas y condición segura de bombas y válvulas. | C30: FALSE | D30: Entrevista técnica guiada + validación con resultados en receta. | E30: HMI/SCADA, históricos de tendencia, alarmas y SOP de respuesta; P&ID, matriz de válvulas, secuencia de operación/CIP y checklist de ruta; Checklist de bombas/sellos, alineador, comparador, vibrómetro y manual OEM
B31: FILTRO DE MOSTO | C31: =IFERROR(COUNTIF(C32:C43,TRUE)/COUNTA(B32:B43),0) -> 0 | D31: Método de validación sugerido | E31: ='L7 Elaboración'!E3 -> Herramientas / referencia | F31: ='L7 Elaboración'!F3 -> Comentarios / plan de acción
B32: Comprende el funcionamiento de los principales equipos y componentes del sistema de filtración de mosto: lauter tun o mash filter, fondo falso/telas/placas, cuchillas/rakes, sistema hidráulico, bombas, sistema desalojo de bagazo, válvulas e instrumentación. | C32: FALSE | D32: Entrevista técnica guiada + identificación física de equipos/componentes en campo. | E32: P&ID, matriz de válvulas, secuencia de operación/CIP y checklist de ruta; Turbidímetro, medidor de O₂ disuelto, dP, caudal, SOP de filtración y registros de calidad; Matriz CIP, registro de conductividad/temperatura/tiempo, ATP/micro si aplica
B33: Explica las etapas del ciclo y es capaz de identificar la secuencia en los pasos de la receta: Llenado, formación de cama, recirculación, filtración, lavado de bagazo, drenaje, descarga de bagazo y limpieza CIP. | C33: FALSE | D33: Entrevista técnica guiada + identificación física de equipos/componentes en campo. | E33: P&ID, matriz de válvulas, secuencia de operación/CIP y checklist de ruta; Turbidímetro, medidor de O₂ disuelto, dP, caudal, SOP de filtración y registros de calidad; Matriz CIP, registro de conductividad/temperatura/tiempo, ATP/micro si aplica
B34: Interpreta variables críticas: Turbidez, caudal, nivel, presión diferencial, temperatura, extracto de lavado y estabilidad del flujo de mosto. Es capaz de identificar en el SCADA cuando se presenta una falla en el instrumento de medición y genera un avisos de mantenimiento. | C34: FALSE | D34: Prueba práctica en Scada/campo con checklist y explicación de criterio de aceptación. | E34: HMI/SCADA, históricos de tendencia, alarmas y SOP de respuesta; Turbidímetro, medidor de O₂ disuelto, dP, caudal, SOP de filtración y registros de calidad
B35: Relaciona molienda, viscosidad de maceración y operación de cuchillas y falso fondo/ telas y membranas con filtrabilidad, claridad de mosto, rendimiento y tiempo total de ciclo. | C35: FALSE | D35: Entrevista técnica guiada + identificación física de equipos/componentes en campo. | E35: Tamices/granulometría, galgas, amperímetro, manual OEM y checklist de molino; Turbidímetro, medidor de O₂ disuelto, dP, caudal, SOP de filtración y registros de calidad
B36: Verifica condición operaciónal de bombas de recirculación, bombas de mosto, sistema hidráulico, válvulas de transferencia, válvulas de lavado y retorno, identificando cavitación, pérdida de capacidad, aumento de amperaje. | C36: FALSE | D36: Prueba práctica en Scada/campo con checklist y explicación de criterio de aceptación. | E36: P&ID, matriz de válvulas, secuencia de operación/CIP y checklist de ruta; Turbidímetro, medidor de O₂ disuelto, dP, caudal, SOP de filtración y registros de calidad; Checklist de bombas/sellos, alineador, comparador, vibrómetro y manual OEM
B37: Explica la función de cuchilla, profundidad de corte, velocidad y secuencia, reconociendo el impacto de un ajuste incorrecto sobre la cama filtrante. Es capaz de realizar la regulación de ser requerido. | C37: FALSE | D37: Entrevista técnica guiada + identificación física de equipos/componentes en campo. | E37: P&ID, matriz de válvulas, secuencia de operación/CIP y checklist de ruta; Turbidímetro, medidor de O₂ disuelto, dP, caudal, SOP de filtración y registros de calidad
B38: Reconoce la función del sistema hidráulico o de prensado, identificando presión, movimientos, cilindros, actuadores, finales de carrera y riesgos por energía acumulada. Valida el tipo y nivel de aceite requerido. | C38: FALSE | D38: Prueba práctica en Scada/campo con checklist y explicación de criterio de aceptación. | E38: Turbidímetro, medidor de O₂ disuelto, dP, caudal, SOP de filtración y registros de calidad; Informe de análisis de aceite, viscosidad, partículas, agua, ferrografía y tendencia
B39: Identifica los componentes del sistema de remoción y desalojo de bagazo (tolva de bagazo). Participa en ajuste y verificación de alineamiento rutinario. | C39: FALSE | D39: Prueba práctica en Scada/campo con checklist y explicación de criterio de aceptación. | E39: Turbidímetro, medidor de O₂ disuelto, dP, caudal, SOP de filtración y registros de calidad; Matriz CIP, registro de conductividad/temperatura/tiempo, ATP/micro si aplica; Checklist de bombas/sellos, alineador, comparador, vibrómetro y manual OEM
B40: Participa en actividades de mantenimiento básicas como limpieza mecánica de falso fondo: Desarmado, limpieza y armado de falso fondo para filtro lauter. Para mash filter participa en el reemplazo de telas y membranas filtrantes. | C40: FALSE | D40: Entrevista técnica guiada + identificación física de equipos/componentes en campo. | E40: Turbidímetro, medidor de O₂ disuelto, dP, caudal, SOP de filtración y registros de calidad; Matriz CIP, registro de conductividad/temperatura/tiempo, ATP/micro si aplica
...

Sheet L7 Elaboración
A1: #VALUE! | B1: Guía Técnica L7 Elaboración
A2: INSTRUCCIONES: 1.Aplicable a operadores, técnicos mecánicos y PTE en el/los proceso(s) que corresponda 2. Seleccionar las casillas de las habilidades con las que ya cuenta la persona evaluada 3. Dejar vacía las casillas de las habilidades que aún no están desarrolladas en la persona evaluada y registrar plan de acción en "Plan de Cierre de Brechas" 4. No están permitido NA sin previa validación de Director Zonal de Mantenimiento | C2: ="COMPETENCIAS [X] Competente [ ] No competente "&IF(C4>=80%,"≧80% COMPETENTE","< 80% NO COMPETENTE") -> COMPETENCIAS [X] Competente [ ] No competente ≧80% COMPETENTE
B3: MANEJO DE MATERIA PRIMA | C3: =IFERROR(COUNTIF(C4:C13,TRUE)/COUNTA(B4:B13),0) -> 0 | D3: Método de validación sugerido | E3: Herramientas / referencia | F3: Comentarios / plan de acción
B4: Inspecciona transportadores, elevadores, cadenas, bandas, cangilones, raspadores y guardas, identificando desgaste, elongación, desalineación, fisuras y fijaciones sueltas. | C4: FALSE | D4: Evaluación práctica DTO de intervención + inspección de componentes según SWI de actividad | E4: Checklist de transporte/aspiración, manómetro/dP, tacómetro y registros PM; Checklist de bombas/sellos, alineador, comparador, vibrómetro y manual OEM
B5: Participa en la intervención mecánica en cangilones, bandas, cadenas, poleas, raspadores, compuertas y elementos de fijación, aplicando bloqueo de energías y procedimientos estandarizados. | C5: FALSE | D5: Evaluación práctica DTO de intervención + inspección de componentes según SWI de actividad | E5: Checklist de transporte/aspiración, manómetro/dP, tacómetro y registros PM; Matriz CIP, registro de conductividad/temperatura/tiempo, ATP/micro si aplica
B6: Interpreta planos P&D mecánicos, eléctricos y neumáticos básicos para aislar, intervenir y liberar equipos de materia prima con control de energías peligrosas. | C6: FALSE | D6: Revisión de P&ID/plano/secuencia. Explicación en campo. | E6: P&ID, matriz de válvulas, secuencia de operación/CIP y checklist de ruta; Checklist de transporte/aspiración, manómetro/dP, tacómetro y registros PM
B7: Evalúa rodamientos, chumaceras, reductores, acoplamientos, sellos y soportes, definiendo si requieren ajuste, lubricación, reemplazo o seguimiento por condición. | C7: FALSE | D7: Evaluación práctica DTO de intervención + inspección de componentes según SWI de actividad | E7: Checklist de bombas/sellos, alineador, comparador, vibrómetro y manual OEM; Informe de análisis de aceite, viscosidad, partículas, agua, ferrografía y tendencia
B8: Realiza inspección interna de filtros de mangas, colectores, ductos, ventiladores y sistemas de pulso, verificando taponamiento, rotura, fugas, corrosión y hermeticidad. | C8: FALSE | D8: Evaluación práctica DTO de intervención + inspección de componentes según SWI de actividad | E8: Checklist de transporte/aspiración, manómetro/dP, tacómetro y registros PM
B9: Verifica básculas, celdas de carga, sensores de nivel, desvío de banda y detectores de atasco después de una intervención mecánica o eléctrica. | C9: FALSE | D9: Evaluación práctica DTO de intervención + inspección de componentes según SWI de actividad | E9: P&ID, manual OEM, procedimiento LOTO, kit de herramientas y checklist de intervención
B10: Alinea poleas, acoples y transmisiones, validando tensión, paralelismo, sentido de giro, ausencia de fricción, vibración anormal y calentamiento. | C10: FALSE | D10: Evaluación práctica DTO de intervención + inspección de componentes según SWI de actividad | E10: P&ID de vapor/condensado, termografía, manómetros y registros de rampa térmica; Checklist de bombas/sellos, alineador, comparador, vibrómetro y manual OEM; Analizador de vibraciones, espectros/tendencias, rutas CBM y límites de severidad
B11: Participa en el análisis para corrección de fallas típicas en compuertas, actuadores, sensores y enclavamientos locales, diferenciando falla mecánica, neumática, eléctrica o de señal. | C11: FALSE | D11: Caso análisis de falla + revisión + diagnóstico y acción realizada. | E11: P&ID, manual OEM, procedimiento LOTO, kit de herramientas y checklist de intervención
B12: Realiza pruebas funcionales sin carga y con carga controlada, confirmando capacidad, estabilidad, limpieza técnica, secuencia automática y retorno seguro a operación. | C12: FALSE | D12: Prueba funcional post-intervención con checklist de aceptación y liberación segura. | E12: P&ID, matriz de válvulas, secuencia de operación/CIP y checklist de ruta
B13: Documenta hallazgos de intervención indicando equipo, componente, modo de falla, causa probable, repuesto utilizado, condición final y recomendación preventiva. | C13: FALSE | D13: Revisión de Orden Trabajo + validación de calidad del reporte técnico. | E13: P&ID, manual OEM, procedimiento LOTO, kit de herramientas y checklist de intervención
B14: MOLIENDA | C14: =IFERROR(COUNTIF(C15:C25,TRUE)/COUNTA(B15:B25),0) -> 0 | D14: =D3 -> Método de validación sugerido | E14: =E3 -> Herramientas / referencia | F14: =F3 -> Comentarios / plan de acción
B15: Inspecciona alimentadores, imanes, compuertas, rodillos, martillos, cribas, placa perforada, rotoesclusa, rodamientos y sistemas de aspiración. | C15: FALSE | D15: Evaluación práctica DTO de intervención + inspección de componentes según SWI de actividad | E15: Checklist de transporte/aspiración, manómetro/dP, tacómetro y registros PM; Tamices/granulometría, galgas, amperímetro, manual OEM y checklist de molino
B16: Ejecuta reemplazo, ajuste o calibración mecánica de rodillos, martillos, cribas, placas perforadas, sellos, rodamientos y fijaciones según tecnología instalada y estándar del fabricante. | C16: FALSE | D16: Evaluación práctica DTO de intervención + inspección de componentes según SWI de actividad | E16: Tamices/granulometría, galgas, amperímetro, manual OEM y checklist de molino; Checklist de bombas/sellos, alineador, comparador, vibrómetro y manual OEM
B17: Verifica gap/luz de rodillos, paralelismo, presión de molienda, balance de rotor, condición de martillos/cribas y uniformidad de alimentación. | C17: FALSE | D17: Evaluación práctica DTO de intervención + inspección de componentes según SWI de actividad | E17: Tamices/granulometría, galgas, amperímetro, manual OEM y checklist de molino
B18: Evalúa motores, reductores, acoplamientos, correas, poleas y cadenas relacionando condición mecánica con capacidad y consumo eléctrico. | C18: FALSE | D18: Evaluación práctica DTO de intervención + inspección de componentes según SWI de actividad | E18: Tamices/granulometría, galgas, amperímetro, manual OEM y checklist de molino
B19: Realiza limpieza técnica e inspección de filtros de polvo, ductos, ventiladores, mangas, esclusas y puntos de captación del sistema de molienda. | C19: FALSE | D19: Evaluación práctica DTO de intervención + inspección de componentes según SWI de actividad | E19: Checklist de transporte/aspiración, manómetro/dP, tacómetro y registros PM; Tamices/granulometría, galgas, amperímetro, manual OEM y checklist de molino
B20: Participa en el análisis para corrección de fallas típicas de molienda: vibración, ruido metálico, sobrecorriente, baja capacidad, atascamiento, calentamiento y variación de granulometría. | C20: FALSE | D20: Caso análisis de falla + revisión + diagnóstico y acción realizada. | E20: Tamices/granulometría, galgas, amperímetro, manual OEM y checklist de molino; P&ID de vapor/condensado, termografía, manómetros y registros de rampa térmica; Matriz CIP, registro de conductividad/temperatura/tiempo, ATP/micro si aplica
B21: Interpreta planos P&D mecánicos, eléctricos y neumáticos básicos para aislar, intervenir y liberar equipos de molienda con control de energías peligrosas. | C21: FALSE | D21: Revisión de P&ID/plano/secuencia. Explicación en campo. | E21: P&ID, matriz de válvulas, secuencia de operación/CIP y checklist de ruta; Tamices/granulometría, galgas, amperímetro, manual OEM y checklist de molino
B22: Valida enclavamientos de seguridad, sensores de apertura, velocidad, nivel, presión diferencial, detectores metálicos e interlocks después de mantenimiento. | C22: FALSE | D22: Evaluación práctica DTO de intervención + inspección de componentes según SWI de actividad | E22: Tamices/granulometría, galgas, amperímetro, manual OEM y checklist de molino
B23: Ejecuta lubricación técnica, cambio de aceite/grasa y verificación de puntos críticos, evitando contaminación de producto y sobrelubricación. | C23: FALSE | D23: Evaluación práctica DTO de intervención + inspección de componentes según SWI de actividad | E23: Tamices/granulometría, galgas, amperímetro, manual OEM y checklist de molino; Informe de análisis de aceite, viscosidad, partículas, agua, ferrografía y tendencia
B24: Realiza prueba de molienda con carga controlada, validando granulometría, estabilidad mecánica, consumo, ausencia de fugas de polvo y cumplimiento del proceso. | C24: FALSE | D24: Prueba funcional post-intervención con checklist de aceptación y liberación segura.
B25: Documenta hallazgos de intervención indicando equipo, componente, modo de falla, causa probable, repuesto utilizado, condición final y recomendación preventiva. | C25: FALSE | D25: Revisión de Orden Trabajo + validación de calidad del reporte técnico. | E25: Checklist de transporte/aspiración, manómetro/dP, tacómetro y registros PM; Tamices/granulometría, galgas, amperímetro, manual OEM y checklist de molino
B26: MACERACIÓN | C26: =IFERROR(COUNTIF(C27:C36,TRUE)/COUNTA(B27:B36),0) -> 0 | D26: =D3 -> Método de validación sugerido | E26: =E3 -> Herramientas / referencia | F26: =F3 -> Comentarios / plan de acción
B27: Inspecciona cocedor, macerador, agitadores, ejes, paletas, reductores, acoplamientos, sellos, soportes y bombas de macerado, identificando holguras, desgaste y fugas. | C27: FALSE | D27: Evaluación práctica DTO de intervención + inspección de componentes según SWI de actividad | E27: Checklist de bombas/sellos, alineador, comparador, vibrómetro y manual OEM
B28: Ejecuta mantenimiento de agitadores, acoples, sellos mecánicos, empaques, rodamientos, reductores y bases, aplicando alineación y torque según estándar. | C28: FALSE | D28: Evaluación práctica DTO de intervención + inspección de componentes según SWI de actividad | E28: Checklist de bombas/sellos, alineador, comparador, vibrómetro y manual OEM
B29: Verifica chaquetas de calentamiento, serpentines, calandria, válvulas de vapor, trampas, retorno de condensado y aislamiento térmico, identificando restricciones, fugas o baja transferencia. | C29: FALSE | D29: Evaluación práctica DTO de intervención + inspección de componentes según SWI de actividad | E29: P&ID, matriz de válvulas, secuencia de operación/CIP y checklist de ruta; P&ID de vapor/condensado, termografía, manómetros y registros de rampa térmica
B30: Interviene bombas de macerado, válvulas de transferencia, actuadores neumáticos y posicionadores, validando estanqueidad y respuesta funcional. | C30: FALSE | D30: Evaluación práctica DTO de intervención + inspección de componentes según SWI de actividad | E30: P&ID, matriz de válvulas, secuencia de operación/CIP y checklist de ruta; Checklist de bombas/sellos, alineador, comparador, vibrómetro y manual OEM
B31: Evalúa instrumentos de temperatura, nivel, caudal, presión y pH, coordinando calibración/verificación cuando la medición afecte receta o seguridad. | C31: FALSE | D31: Evaluación práctica DTO de intervención + inspección de componentes según SWI de actividad | E31: P&ID, manual OEM, procedimiento LOTO, kit de herramientas y checklist de intervención
B32: Inspecciona sistema CIP: roto-jet, boquillas, líneas, drenajes, válvulas de retorno, conductividad y temperatura, detectando baja cobertura o zonas muertas. | C32: FALSE | D32: Evaluación práctica DTO de intervención + inspección de componentes según SWI de actividad | E32: P&ID, matriz de válvulas, secuencia de operación/CIP y checklist de ruta; Matriz CIP, registro de conductividad/temperatura/tiempo, ATP/micro si aplica
B33: Participa en el análisis para corrección de fallas de mezcla, calentamiento, transferencia o limpieza que afecten rampas térmicas, conversión, viscosidad, inocuidad y disponibilidad del equipo. | C33: FALSE | D33: Caso análisis de falla + revisión + diagnóstico y acción realizada. | E33: P&ID de vapor/condensado, termografía, manómetros y registros de rampa térmica; Matriz CIP, registro de conductividad/temperatura/tiempo, ATP/micro si aplica
B34: Interpreta P&ID, planos mecánicos y secuencias de proceso para aislar maceradores, bombas y líneas antes de una intervención. | C34: FALSE | D34: Revisión de P&ID/plano/secuencia. Explicación en campo. | E34: P&ID, matriz de válvulas, secuencia de operación/CIP y checklist de ruta; Checklist de bombas/sellos, alineador, comparador, vibrómetro y manual OEM
B35: Realiza prueba funcional de agitador, bombas, válvulas, calentamiento y CIP antes de liberar el sistema a producción. | C35: FALSE | D35: Prueba funcional post-intervención con checklist de aceptación y liberación segura. | E35: P&ID, matriz de válvulas, secuencia de operación/CIP y checklist de ruta; P&ID de vapor/condensado, termografía, manómetros y registros de rampa térmica; Matriz CIP, registro de conductividad/temperatura/tiempo, ATP/micro si aplica
B36: Documenta condición final indicando componente intervenido, modo de falla, repuestos, pruebas realizadas, riesgos remanentes y criterios de liberación. | C36: FALSE | D36: Revisión de Orden Trabajo + validación de calidad del reporte técnico. | E36: P&ID, manual OEM, procedimiento LOTO, kit de herramientas y checklist de intervención
B37: FILTRO DE MOSTO | C37: =IFERROR(COUNTIF(C38:C48,TRUE)/COUNTA(B38:B48),0) -> 0 | D37: =D3 -> Método de validación sugerido | E37: =E3 -> Herramientas / referencia | F37: =F3 -> Comentarios / plan de acción
B38: Inspecciona lauter tun o mash filter identificando desgaste, deformación, daño sanitario, obstrucción, holguras, fugas y condición de superficies en contacto con producto. | C38: FALSE | D38: Evaluación práctica DTO de intervención + inspección de componentes según SWI de actividad | E38: Turbidímetro, medidor de O₂ disuelto, dP, caudal, SOP de filtración y registros de calidad; Matriz CIP, registro de conductividad/temperatura/tiempo, ATP/micro si aplica
B39: Ejecuta mantenimiento de cuchillas/rakes, ejes, reductores, válvulas, actuadores, cilindros, telas, placas, fondo falso, empaques y elementos de fijación según tecnología instalada. | C39: FALSE | D39: Evaluación práctica DTO de intervención + inspección de componentes según SWI de actividad | E39: P&ID, matriz de válvulas, secuencia de operación/CIP y checklist de ruta; Turbidímetro, medidor de O₂ disuelto, dP, caudal, SOP de filtración y registros de calidad
B40: Verifica bombas de recirculación, bombas de mosto, válvulas de trasiego/lavado, válvulas de drenaje y actuadores, validando caudal, estanqueidad y respuesta. | C40: FALSE | D40: Evaluación práctica DTO de intervención + inspección de componentes según SWI de actividad | E40: P&ID, matriz de válvulas, secuencia de operación/CIP y checklist de ruta; Turbidímetro, medidor de O₂ disuelto, dP, caudal, SOP de filtración y registros de calidad; Checklist de bombas/sellos, alineador, comparador, vibrómetro y manual OEM
...

Sheet L8 Elaboración
A1: #VALUE! | B1: Guía Técnica L8 Elaboración
A2: INSTRUCCIONES: 1. Aplicable a operadores, técnicos mecánicos y PTE en el/los proceso(s) que corresponda 2. Seleccionar las casillas de las habilidades con las que ya cuenta la persona evaluada 3. Dejar vacía las casillas de las habilidades que aún no están desarrolladas en la persona evaluada y registrar plan de acción en "Plan de Cierre de Brechas" 4. No están permitido NA sin previa validación de Director Zonal de Mantenimiento | C2: ="COMPETENCIAS [X] Competente [ ] No competente "&IF(C4>=80%,"≧80% COMPETENTE","< 80% NO COMPETENTE") -> COMPETENCIAS [X] Competente [ ] No competente ≧80% COMPETENTE
B3: MANEJO DE MATERIA PRIMA | C3: =IFERROR(COUNTIF(C4:C9,TRUE)/COUNTA(B4:B9),0) -> 0 | D3: ='L7 Elaboración'!D3 -> Método de validación sugerido | E3: ='L7 Elaboración'!E3 -> Herramientas / referencia | F3: ='L7 Elaboración'!F3 -> Comentarios / plan de acción
B4: Interpreta resultados de análisis de vibración en motores, reductores, ventiladores, elevadores y transportadores. Relaciona los resultados con principales fallas por condiciones relacionadas a desbalance, desalineación, holgura y falla de rodamientos. | C4: FALSE | D4: Interpretación de reporte predictivo real/simulado + diagnóstico de severidad y acción realizada. | E4: Checklist de transporte/aspiración, manómetro/dP, tacómetro y registros PM; Matriz CIP, registro de conductividad/temperatura/tiempo, ATP/micro si aplica; Checklist de bombas/sellos, alineador, comparador, vibrómetro y manual OEM
B5: Interpreta resultados de análisis de termografía en motores, rodamientos, reductores y puntos de fricción. Relaciona los resultados con principales fallas por fricción, exceso de carga y lubricación deficiente. | C5: FALSE | D5: Interpretación de reporte predictivo real/simulado + diagnóstico de severidad y acción realizada. | E5: Matriz CIP, registro de conductividad/temperatura/tiempo, ATP/micro si aplica; Cámara termográfica, informe IR, cargas eléctricas/térmicas y tendencia histórica; Informe de análisis de aceite, viscosidad, partículas, agua, ferrografía y tendencia
B6: Interpreta resultados de análisis de ultrasonido para detectar fugas neumáticas, fricción, falla incipiente de rodamientos, descarga parcial y pérdidas de aspiración en sistemas de polvo. | C6: FALSE | D6: Interpretación de reporte predictivo real/simulado + diagnóstico de severidad y acción realizada. | E6: Checklist de transporte/aspiración, manómetro/dP, tacómetro y registros PM; Matriz CIP, registro de conductividad/temperatura/tiempo, ATP/micro si aplica; Equipo de ultrasonido, ruta de fugas/rodamientos, dB/FFT y reporte predictivo
B7: Interpreta resultados de análisis de aceite en reductores, sistemas de bombeo y sistemas hidráulicos, relaciona con fallas de desgaste en piezas mecánicas (partículas en aceite) y viscosidad. | C7: FALSE | D7: Interpretación de reporte predictivo real/simulado + diagnóstico de severidad y acción realizada. | E7: Informe de análisis de aceite, viscosidad, partículas, agua, ferrografía y tendencia
B8: Identifica y correlaciona comportamiento de presión diferencial de filtros de polvo, amperaje, alarmas de atasco y capacidad transportada para anticipar fallas y pérdida de confiabilidad. | C8: FALSE | D8: Análisis de condición/tendencias + caso de falla funcional + recomendación técnica. | E8: HMI/SCADA, históricos de tendencia, alarmas y SOP de respuesta; Checklist de transporte/aspiración, manómetro/dP, tacómetro y registros PM; Matriz CIP, registro de conductividad/temperatura/tiempo, ATP/micro si aplica
B9: Participa en elaboración de RCM y/o CBM para transportadores, elevadores, limpiadoras, aspiradores y básculas, priorizando modos de falla por seguridad, producción y calidad. Interpreta los resultados y entiende los beneficios en su proceso. | C9: FALSE | D9: Caso RCM/CBM + revisión de criticidad, modo de falla, tarea propuesta y beneficio. | E9: Checklist de transporte/aspiración, manómetro/dP, tacómetro y registros PM; Matriz CIP, registro de conductividad/temperatura/tiempo, ATP/micro si aplica; Matriz RCM/CBM, AFJ, historial de fallas, criticidad, PM/WO y toolkit corporativo
B10: MOLIENDA | C10: =IFERROR(COUNTIF(C11:C15,TRUE)/COUNTA(B11:B15),0) -> 0 | D10: =D3 -> Método de validación sugerido | E10: =E3 -> Herramientas / referencia | F10: =F3 -> Comentarios / plan de acción
B11: Interpreta resultados de análisis de vibración en molienda, motor, reductor, rodamientos, molino y ventiladores. Relaciona los resultados con principales fallas por condiciones relacionadas a desbalance, desalineación, holgura y falla de rodamientos. | C11: FALSE | D11: Interpretación de reporte predictivo real/simulado + diagnóstico de severidad y acción realizada. | E11: Tamices/granulometría, galgas, amperímetro, manual OEM y checklist de molino; Matriz CIP, registro de conductividad/temperatura/tiempo, ATP/micro si aplica; Checklist de bombas/sellos, alineador, comparador, vibrómetro y manual OEM
B12: Interpreta resultados de análisis de termografía en motores, rodamientos, reductores y puntos de fricción. Relaciona los resultados con sobrecarga y lubricación deficiente. | C12: FALSE | D12: Interpretación de reporte predictivo real/simulado + diagnóstico de severidad y acción realizada. | E12: Tamices/granulometría, galgas, amperímetro, manual OEM y checklist de molino; Cámara termográfica, informe IR, cargas eléctricas/térmicas y tendencia histórica; Informe de análisis de aceite, viscosidad, partículas, agua, ferrografía y tendencia
B13: Interpreta resultados de análisis de ultrasonido para detectar fugas neumáticas, fricción, falla incipiente de rodamientos, descarga parcial y pérdidas de aspiración en sistemas de molienda. | C13: FALSE | D13: Interpretación de reporte predictivo real/simulado + diagnóstico de severidad y acción realizada. | E13: Checklist de transporte/aspiración, manómetro/dP, tacómetro y registros PM; Tamices/granulometría, galgas, amperímetro, manual OEM y checklist de molino; Matriz CIP, registro de conductividad/temperatura/tiempo, ATP/micro si aplica
B14: Interpreta resultados de condición de lubricantes (análisis de aceites), identificando contaminación, temperatura y partículas en reductores o sistemas centralizados, definiendo severidad y ventana de intervención. | C14: FALSE | D14: Interpretación de reporte predictivo real/simulado + diagnóstico de severidad y acción realizada. | E14: Tamices/granulometría, galgas, amperímetro, manual OEM y checklist de molino; Informe de análisis de aceite, viscosidad, partículas, agua, ferrografía y tendencia
B15: Participa en la elaboración de CBM y/o RCM de molinos considerando impacto en extracción, filtrabilidad, consumo energético y tiempo de ciclo. Interpreta resultados y entiende los beneficios en su proceso. | C15: FALSE | D15: Caso RCM/CBM + revisión de criticidad, modo de falla, tarea propuesta y beneficio. | E15: Tamices/granulometría, galgas, amperímetro, manual OEM y checklist de molino; Matriz CIP, registro de conductividad/temperatura/tiempo, ATP/micro si aplica; Matriz RCM/CBM, AFJ, historial de fallas, criticidad, PM/WO y toolkit corporativo
B16: MACERACIÓN | C16: =IFERROR(COUNTIF(C17:C24,TRUE)/COUNTA(B17:B24),0) -> 0 | D16: =D3 -> Método de validación sugerido | E16: =E3 -> Herramientas / referencia | F16: =F3 -> Comentarios / plan de acción
B17: Interpreta resultados de análisis de vibración en reductores, motores, bombas y acoplamientos para detectar desalineación, falla de rodamientos, cavitación o pérdida de balance. | C17: FALSE | D17: Interpretación de reporte predictivo real/simulado + diagnóstico de severidad y acción realizada. | E17: Checklist de bombas/sellos, alineador, comparador, vibrómetro y manual OEM; Analizador de vibraciones, espectros/tendencias, rutas CBM y límites de severidad
B18: Interpreta resultados de análisis de termografía en motores, reductores y puntos de fricción. | C18: FALSE | D18: Interpretación de reporte predictivo real/simulado + diagnóstico de severidad y acción realizada. | E18: Cámara termográfica, informe IR, cargas eléctricas/térmicas y tendencia histórica
B19: Interpreta resultados de análisis de termografía en trampas de vapor identificando su correcto funcionamiento e impactos en consumo energético. | C19: FALSE | D19: Interpretación de reporte predictivo real/simulado + diagnóstico de severidad y acción realizada. | E19: P&ID de vapor/condensado, termografía, manómetros y registros de rampa térmica; Cámara termográfica, informe IR, cargas eléctricas/térmicas y tendencia histórica
B20: Interpreta resultados de análisis de aceite en reductores, sistemas de bombeo y sistemas hidráulicos, relaciona con fallas de desgaste en piezas mecánicas (partículas en aceite) y viscosidad. | C20: FALSE | D20: Interpretación de reporte predictivo real/simulado + diagnóstico de severidad y acción realizada. | E20: Informe de análisis de aceite, viscosidad, partículas, agua, ferrografía y tendencia
B21: Analiza comportamiento de los principales lazos de control para anticipar inestabilidad o pérdida de control del proceso. Conoce y es capaz de sugerir ajustes en controladores PID. | C21: FALSE | D21: Análisis de condición/tendencias + caso de falla funcional + recomendación técnica. | E21: Matriz CIP, registro de conductividad/temperatura/tiempo, ATP/micro si aplica
B22: Interpreta y conoce los beneficios del monitoreo de condiciones AFJ (Alarmas, Fallas y Forzados)/ ISA (Indicador de Salud de Automatización) . Evidencia control y seguimiento. | C22: FALSE | D22: Caso AFJ + revisión de Alarmas, Fallas y Forzados + diagnóstico y acción realizada. | E22: HMI/SCADA, históricos de tendencia, alarmas y SOP de respuesta; Matriz RCM/CBM, AFJ, historial de fallas, criticidad, PM/WO y toolkit corporativo
B23: Interpreta y participa en el desarrollo del Toolkit de Válvulas y Bombas de Brewingrewing. Analisa resultados y genera avisos de mantenimiento. Evidencia control y seguimiento. | C23: FALSE | D23: Revisión de Toolkit, reporte mensual de avances + plan de trabajo 1YP | E23: P&ID, matriz de válvulas, secuencia de operación/CIP y checklist de ruta; Matriz CIP, registro de conductividad/temperatura/tiempo, ATP/micro si aplica; Checklist de bombas/sellos, alineador, comparador, vibrómetro y manual OEM
B24: Participa en la elaboración de CBM y/o RCM de los principales equipos del sistema de maceración priorizando modos de falla que afecten conversión, mezcla, inocuidad, seguridad por vapor y disponibilidad. | C24: FALSE | D24: Caso RCM/CBM + revisión de criticidad, modo de falla, tarea propuesta y beneficio. | E24: P&ID de vapor/condensado, termografía, manómetros y registros de rampa térmica; Matriz CIP, registro de conductividad/temperatura/tiempo, ATP/micro si aplica; Matriz RCM/CBM, AFJ, historial de fallas, criticidad, PM/WO y toolkit corporativo
B25: FILTRO DE MOSTO | C25: =IFERROR(COUNTIF(C26:C32,TRUE)/COUNTA(B26:B32),0) -> 0 | D25: =D3 -> Método de validación sugerido | E25: =E3 -> Herramientas / referencia | F25: =F3 -> Comentarios / plan de acción
B26: Interpreta resultados de análisis de vibración en reductores, motores, bombas y acoplamientos para detectar desalineación, falla de rodamientos, cavitación o pérdida de balance. | C26: FALSE | D26: Interpretación de reporte predictivo real/simulado + diagnóstico de severidad y acción realizada. | E26: Turbidímetro, medidor de O₂ disuelto, dP, caudal, SOP de filtración y registros de calidad; Checklist de bombas/sellos, alineador, comparador, vibrómetro y manual OEM; Analizador de vibraciones, espectros/tendencias, rutas CBM y límites de severidad
B27: Interpreta resultados de análisis de termografía aplicado a anillos colectores, calentadores de cascos tubos y placas a fin de determinar deficiciencia en transferencia de calor, obstrucciones, perdidas de flujo. | C27: FALSE | D27: Interpretación de reporte predictivo real/simulado + diagnóstico de severidad y acción realizada. | E27: P&ID de vapor/condensado, termografía, manómetros y registros de rampa térmica; Turbidímetro, medidor de O₂ disuelto, dP, caudal, SOP de filtración y registros de calidad; Cámara termográfica, informe IR, cargas eléctricas/térmicas y tendencia histórica
B28: Aplica ultrasonido y termografía para detectar fugas hidráulicas, cavitación, fricción, sobrecalentamiento, aire atrapado o pérdida de eficiencia en actuadores. | C28: FALSE | D28: Interpretación de reporte predictivo real/simulado + diagnóstico de severidad y acción realizada. | E28: P&ID de vapor/condensado, termografía, manómetros y registros de rampa térmica; Turbidímetro, medidor de O₂ disuelto, dP, caudal, SOP de filtración y registros de calidad; Cámara termográfica, informe IR, cargas eléctricas/térmicas y tendencia histórica
B29: Interpreta resultados de análisis de aceite en reductores, sistemas de bombeo y sistemas hidráulicos, relaciona con fallas de desgaste en piezas mecánicas (partículas en aceite) y viscosidad. | C29: FALSE | D29: Interpretación de reporte predictivo real/simulado + diagnóstico de severidad y acción realizada. | E29: Turbidímetro, medidor de O₂ disuelto, dP, caudal, SOP de filtración y registros de calidad; Informe de análisis de aceite, viscosidad, partículas, agua, ferrografía y tendencia
B30: Interpreta y conoce los beneficios del monitoreo de condiciones AFJ (Alarmas, Fallas y Forzados)/ ISA (Indicador de Salud de Automatización) . Evidencia control y seguimiento. | C30: FALSE | D30: Caso AFJ + revisión de Alarmas, Fallas y Forzados + diagnóstico y acción realizada. | E30: HMI/SCADA, históricos de tendencia, alarmas y SOP de respuesta; Turbidímetro, medidor de O₂ disuelto, dP, caudal, SOP de filtración y registros de calidad; Matriz RCM/CBM, AFJ, historial de fallas, criticidad, PM/WO y toolkit corporativo
B31: Interpreta y participa en el desarrollo del Toolkit de Válvulas y Bombas de Brewingrewing. Analisa resultados y genera avisos de mantenimiento. Evidencia control y seguimiento. | C31: FALSE | D31: Revisión de Toolkit, reporte mensual de avances + plan de trabajo 1YP. | E31: P&ID, matriz de válvulas, secuencia de operación/CIP y checklist de ruta; Turbidímetro, medidor de O₂ disuelto, dP, caudal, SOP de filtración y registros de calidad; Matriz CIP, registro de conductividad/temperatura/tiempo, ATP/micro si aplica
B32: Participa en la elaboración de CBM/RCM para lauter tun o mash filter considerando claridad de mosto, rendimiento, tiempo de ciclo, seguridad e impacto en producción. | C32: FALSE | D32: Caso RCM/CBM + revisión de criticidad, modo de falla, tarea propuesta y beneficio. | E32: Turbidímetro, medidor de O₂ disuelto, dP, caudal, SOP de filtración y registros de calidad; Matriz CIP, registro de conductividad/temperatura/tiempo, ATP/micro si aplica; Matriz RCM/CBM, AFJ, historial de fallas, criticidad, PM/WO y toolkit corporativo
B33: SALA DE COCIMIENTO | C33: =IFERROR(COUNTIF(C34:C41,TRUE)/COUNTA(B34:B41),0) -> 0 | D33: =D3 -> Método de validación sugerido | E33: =E3 -> Herramientas / referencia | F33: =F3 -> Comentarios / plan de acción
B34: Interpreta resultados de análisis de vibración en reductores, motores, bombas y acoplamientos para detectar desalineación, falla de rodamientos, cavitación o pérdida de balance. | C34: FALSE | D34: Interpretación de reporte predictivo real/simulado + diagnóstico de severidad y acción realizada. | E34: Checklist de bombas/sellos, alineador, comparador, vibrómetro y manual OEM; Analizador de vibraciones, espectros/tendencias, rutas CBM y límites de severidad
B35: Interpreta resultados de análisis de termografía aplicado a intercambiadores de calor a fin de determinar deficiciencia en transferencia de calor, obstrucciones, perdidas de flujo. | C35: FALSE | D35: Interpretación de reporte predictivo real/simulado + diagnóstico de severidad y acción realizada. | E35: Cámara termográfica, informe IR, cargas eléctricas/térmicas y tendencia histórica
B36: Interpreta resultados de análisis de termografía en trampas de vapor identificando su correcto funcionamiento e impactos en consumo energético. | C36: FALSE | D36: Interpretación de reporte predictivo real/simulado + diagnóstico de severidad y acción realizada. | E36: P&ID de vapor/condensado, termografía, manómetros y registros de rampa térmica; Cámara termográfica, informe IR, cargas eléctricas/térmicas y tendencia histórica
B37: Interpreta resultados de ultrasonido y termografía para detectar fugas hidráulicas, cavitación, fricción, sobrecalentamiento, aire atrapado o pérdida de eficiencia en actuadores. | C37: FALSE | D37: Interpretación de reporte predictivo real/simulado + diagnóstico de severidad y acción realizada. | E37: P&ID de vapor/condensado, termografía, manómetros y registros de rampa térmica; Cámara termográfica, informe IR, cargas eléctricas/térmicas y tendencia histórica; Equipo de ultrasonido, ruta de fugas/rodamientos, dB/FFT y reporte predictivo
B38: Interpreta resultados de análisis de aceite en reductores, sistemas de bombeo y sistemas hidráulicos, relaciona con fallas de desgaste en piezas mecánicas (partículas en aceite) y viscosidad. | C38: FALSE | D38: Interpretación de reporte predictivo real/simulado + diagnóstico de severidad y acción realizada. | E38: Informe de análisis de aceite, viscosidad, partículas, agua, ferrografía y tendencia
B39: Interpreta y conoce los beneficios del monitoreo de condiciones AFJ (Alarmas, Fallas y Forzados)/ ISA (Indicador de Salud de Automatización) . Evidencia control y seguimiento. | C39: FALSE | D39: Caso AFJ + revisión de Alarmas, Fallas y Forzados + diagnóstico y acción realizada. | E39: HMI/SCADA, históricos de tendencia, alarmas y SOP de respuesta; Matriz RCM/CBM, AFJ, historial de fallas, criticidad, PM/WO y toolkit corporativo
B40: Interpreta y participa en el desarrollo del Toolkit de Válvulas y Bombas de Brewingrewing. Analisa resultados y genera avisos de mantenimiento. Evidencia control y seguimiento. | C40: FALSE | D40: Revisión de Toolkit, reporte mensual de avances + plan de trabajo 1YP. | E40: P&ID, matriz de válvulas, secuencia de operación/CIP y checklist de ruta; Matriz CIP, registro de conductividad/temperatura/tiempo, ATP/micro si aplica; Checklist de bombas/sellos, alineador, comparador, vibrómetro y manual OEM
...

Sheet ANEXO - Criterios transversales
B2: CRITERIOS TRANSVERSALES SEPARADOS
B3: PROPÓSITO | C3: Evitar repetición de criterios genéricos en L6, L7 y L8. Las hojas principales quedan específicas por sala/equipo; esta hoja define la base común exigible a todo evaluado.
B5: Nivel | C5: Enfoque | D5: Competencias transversales | E5: Evidencia mínima | F5: Aplicación
B6: L6 | C6: Conocimiento técnico de equipos/salas | D6: Lectura básica de HMI/SCADA, identificación de equipos, variables críticas, riesgos de proceso, rutas, alarmas y criterios de escalamiento. | E6: Explica el flujo, reconoce equipos y variables críticas, identifica condición anormal y comunica sin intervenir fuera de autorización. | F6: Todas las salas de elaboración.
B7: L7 | C7: Mantenimiento correctivo/intermedio y parada mayor | D7: Bloqueo de energías, lectura de P&ID/planos, intervención mecánica/sanitaria, ajuste, reemplazo, pruebas funcionales y documentación técnica. | E7: Ejecuta o sustenta intervención segura, valida pruebas sin carga/con carga, registra modo de falla, causa probable y condición de liberación. | F7: Paradas mayores, correctivos planificados e intervenciones especializadas.
B8: L8 | C8: Predictivo, RCM, CBM y análisis de falla | D8: Vibración, termografía, ultrasonido, análisis de aceite, tendencias de proceso, criticidad, modos de falla, severidad y ventana de intervención. | E8: Interpreta tendencias, define severidad, prioriza intervención y vincula condición del activo con riesgo de producción, seguridad, calidad e inocuidad. | F8: Gestión de confiabilidad y mantenimiento basado en condición.
B10: Regla técnica | C10: Los criterios repetitivos no deben evaluarse como frases genéricas dentro de cada sala. Deben aterrizarse al equipo, variable, componente, modo de falla o riesgo específico de la sala evaluada.
B11: Verbos estándar | C11: Identifica, interpreta, verifica, reconoce, relaciona, ejecuta, corrige, valida, documenta, analiza, correlaciona, define.
B12: Criterio de aprobación | C12: Se considera competente cuando demuestra conocimiento verificable, acción segura, criterio técnico y capacidad de escalamiento. No basta con declarar que “conoce” el sistema.
