Workbook

Sheet Edad_Antigüedad
M1: Años
A2: Area | B2: Prom Experiencia del Equipo | C2: Prom Edad | D2: Total Dias de Vacaciones | E2: Prom Dias de Vacaciones | H2: Area | I2: Mín. Antigüedad | J2: Prom Antigüedad | K2: Máx. Antigüedad | M2: 1 | N2: 12
A3: COCIMIENTOS | B3: 13.857143 | C3: 37.860274 | D3: 1138 | E3: 23.22449 | H3: COCIMIENTOS | I3: 0 | J3: 13.857143 | K3: 30 | M3: 2 | N3: 14
A4: CUARTOS FRIOS | B4: 14.460526 | C4: 39.509625 | D4: 1786 | E4: 23.5 | H4: CUARTOS FRIOS | I4: 1 | J4: 14.460526 | K4: 30 | M4: 3 | N4: 16
A5: ELABORACION | B5: 19 | C5: 42.686301 | D5: 160 | E5: 26.666667 | H5: ELABORACION | I5: 6 | J5: 19 | K5: 27 | M5: 4 | N5: 18
A6: MANTENIMIENTO | B6: 21.212121 | C6: 44.465338 | D6: 884 | E6: 26.787879 | H6: MANTENIMIENTO | I6: 3 | J6: 21.212121 | K6: 30 | M6: 5 | N6: 20
A7: Total general | B7: 15.804878 | C7: 40.130237 | D7: 3968 | E7: 24.195122 | H7: Total general | I7: 0 | J7: 15.804878 | K7: 30 | M7: 6 | N7: 22
M8: 7 | N8: 22
M9: 8 | N9: 22
H10: Area | I10: Mín. Edad | J10: Prom Edad | K10: Máx. Edad | M10: 9 | N10: 22
H11: COCIMIENTOS | I11: 22.657534 | J11: 37.860274 | K11: 55.175342 | M11: 10 | N11: 22
H12: CUARTOS FRIOS | I12: 22.246575 | J12: 39.509625 | K12: 59.509589 | M12: 11 | N12: 24
H13: ELABORACION | I13: 29.49589 | J13: 42.686301 | K13: 52.671233 | M13: 12 | N13: 24
H14: MANTENIMIENTO | I14: 25.142466 | J14: 44.465338 | K14: 57.482192 | M14: 13 | N14: 24
H15: Total general | I15: 22.246575 | J15: 40.130237 | K15: 59.509589 | M15: 14 | N15: 24
M16: 15 | N16: 24
M17: 16 | N17: 26
M18: 17 | N18: 26
M19: 18 | N19: 26
M20: 19 | N20: 26
M21: 20 | N21: 26
M22: 21 | N22: 28
M23: 22 | N23: 28
M24: 23 | N24: 28
M25: 24 | N25: 28
M26: 25 | N26: 28
M27: 26 | N27: 30
... M36: 35 | N36: 32

Sheet EAutonomos
B1: Fecha de actualizacion 17-01-2026
B2: Banda | C2: (Todas)
B4: Departamento | C4: Cuenta de Nombre del Lider | E4: Equipo Autonomo | F4: Integrantes
B5: ELABORACION | C5: 6 | E5: COCIMIENTOS | F5: 48 | H5: Etiquetas de fila | I5: Cuenta de Nombre del Equipo
B6: COCIMIENTOS | C6: 49 | E6: LOS CAZADORES DEL AMARGOR | F6: 10 | H6: COCIMIENTOS | I6: 50
B7: CUARTOS FRIOS | C7: 78 | E7: LOS PANCHITOS | F7: 10 | H7: BREWMAN | I7: 2
B8: MANTENIMIENTO | C8: 33 | E8: MASH-RAINBOW | F8: 9 | H8: CUCHILLAS | I8: 9
B9: Total general | C9: 166 | E9: MOSTO-BOYS | F9: 10 | H9: LOS CAZADORES DEL AMARGOR | I9: 10
E10: CUCHILLAS | F10: 9 | H10: LOS PANCHITOS | I10: 10
E11: CUARTOS FRIOS | F11: 76 | H11: MASH-RAINBOW | I11: 9
E12: LOS BRONCOS | F12: 17 | H12: MOSTO-BOYS | I12: 10
E13: REYES DE LA MEZCLA | F13: 8 | H13: CUARTOS FRIOS | I13: 78
E14: LOS FUERTES DEL FRIO | F14: 17 | H14: ANDAMOS CON TODO | I14: 16
E15: ANDAMOS CON TODO | F15: 17 | H15: BRAVOS DEL FRIO | I15: 17
E16: BRAVOS DEL FRIO | F16: 17 | H16: BREWMAN | I16: 3
E17: MANTENIMIENTO | F17: 30 | H17: LOS BRONCOS | I17: 17
E18: MUNICH | F18: 16 | H18: LOS FUERTES DEL FRIO | I18: 16
E19: NAHUALES | F19: 14 | H19: REYES DE LA MEZCLA | I19: 9
E20: Total general | F20: 154 | H20: (en blanco)
H21: ELABORACION | I21: 4
H22: BREWMAN | I22: 4
H23: MANTENIMIENTO | I23: 33
H24: BREWMAN | I24: 3
H25: MUNICH | I25: 16
H26: NAHUALES | I26: 14
H27: Total general | I27: 165

Sheet Personal Total
G1: Operador de Braumat | H1: Operador | I1: Supervisor líder principal EA
K2: =TODAY() -> 46204 | M2: =PERCENTILE(M4:M159,0.75) -> 26
A3: Departamento | B3: Puesto en en Worday | C3: Banda | D3: SHARP | E3: Integrante | F3: SHARP Lider | G3: Nombre del Lider | H3: Nombre del Equipo | I3: Observaciones | J3: Turno (Para Estructura) | K3: Fecha de Ingreso | L3: Fecha de Nacimiento | M3: Antigüedad | N3: Edad | O3: Dias de Vacaciones | P3: Escolaridad | Q3: Cursos Externos | R3: Materias Primas | S3: Cocedor - Macerador | T3: Filtro-Olla | U3: Determinacion de Platos | V3: Operación Fermentacion | W3: Filtros | X3: BBTS | Y3: Planeacion Cerveza | Z3: Manejo de Inventarios C.Frios | AA3: Operación Blender | AB3: Champion Seguridad | AC3: Champion Ambiental | AD3: Champion Gestion | AE3: Champion Gente | AF3: Champion Calidad | AG3: Champion Logistica | AH3: Champion Mantto | AI3: Especialista PSM Dust | AJ3: Planeacion Cocimientos | AK3: Tecnico Electrico | AL3: Tecnico Electronico | AM3: Tecnico Mecanico | AN3: Supervisor de Mantto | AO3: Planeador de Mantto | AP3: Ayudante de Disolución | AQ3: Preparador | AR3: Relevo y QUAS | AS3: Recibo de Materias Primas | AT3: Recibo de Quimicos | AU3: Tolvas de Bagazo
A4: CUARTOS FRIOS | B4: SUPERVISOR DE CUARTOS FRIOS | C4: 7 | D4: 32052981 | E4: JUAN JOSE MEJIA MONTOYA | F4: 32045961 | G4: JAIME ALEJANDRO LAGUNAS CARRERA | H4: ANDAMOS CON TODO | I4: LIDER DE TURNO | J4: 1 | K4: 38882 | L4: 30123 | M4: =ROUND((($K$2-K4)/365),0) -> 20 | N4: =($K$2-L4)/365 -> 44.057534 | O4: =VLOOKUP(M4,Edad_Antigüedad!$M$2:$N$36,2) -> 26 | P4: LICENCIATURA | Q4: 0 | R4: 0 | S4: 0 | T4: 0 | U4: 0 | V4: 1 | W4: 1 | X4: 1 | Y4: 0 | Z4: 0 | AA4: 0 | AB4: 1 | AC4: 0 | AD4: 0 | AE4: 0 | AF4: 0 | AG4: 0 | AH4: 1
A5: CUARTOS FRIOS | B5: OPERADOR DE PLATOS | C5: AM | D5: 32213349 | E5: PEDRO LUIS RODRIGUEZ GAMEZ | F5: 32052981 | G5: JUAN JOSE MEJIA MONTOYA | H5: ANDAMOS CON TODO | I5: Manejo de tierras filtrantes | J5: 1 | K5: 44757 | L5: 35743 | M5: =ROUND((($K$2-K5)/365),0) -> 4 | N5: =($K$2-L5)/365 -> 28.660274 | O5: =VLOOKUP(M5,Edad_Antigüedad!$M$2:$N$36,2) -> 18 | P5: CURSANDO LIC. | Q5: 0 | R5: 0 | S5: 0 | T5: 0 | U5: 1 | V5: 0 | W5: 0 | X5: 0 | Y5: 0 | Z5: 0 | AA5: 0
A6: CUARTOS FRIOS | B6: BOMBERO DE CERVEZA | C6: AM | D6: 32144777 | E6: OSCAR CAMPOS GUERRERO | F6: 32052981 | G6: JUAN JOSE MEJIA MONTOYA | H6: ANDAMOS CON TODO | I6: Bombero de cerveza | J6: 1 | K6: 42357 | L6: 32835 | M6: =ROUND((($K$2-K6)/365),0) -> 11 | N6: =($K$2-L6)/365 -> 36.627397 | O6: =VLOOKUP(M6,Edad_Antigüedad!$M$2:$N$36,2) -> 24 | P6: SECUNDARIA | Q6: 0 | R6: 0 | S6: 0 | T6: 0 | U6: 0 | V6: 1 | W6: 1 | X6: 0 | Y6: 0 | Z6: 0 | AA6: 0
A7: CUARTOS FRIOS | B7: LLENADOR DE GOBIERNO | C7: AM | D7: 32157221 | E7: JESUS MENCHACA DEL VILLAR | F7: 32052981 | G7: JUAN JOSE MEJIA MONTOYA | H7: ANDAMOS CON TODO | I7: Llenador de gobierno | J7: 1 | K7: 42797 | L7: 33550 | M7: =ROUND((($K$2-K7)/365),0) -> 9 | N7: =($K$2-L7)/365 -> 34.668493 | O7: =VLOOKUP(M7,Edad_Antigüedad!$M$2:$N$36,2) -> 22 | P7: PREPARATORIA | Q7: 0 | R7: 0 | S7: 0 | T7: 0 | U7: 0 | V7: 0 | W7: 0 | X7: 0 | Y7: 0 | Z7: 0 | AA7: 0
A8: CUARTOS FRIOS | B8: LLENADOR DE GOBIERNO | C8: AM | D8: 32043849 | E8: PEDRO ANTONIO URIBE ARANDA | F8: 32052981 | G8: JUAN JOSE MEJIA MONTOYA | H8: ANDAMOS CON TODO | I8: Llenador de gobierno | J8: 1 | K8: 35282 | L8: 25017 | M8: =ROUND((($K$2-K8)/365),0) -> 30 | N8: =($K$2-L8)/365 -> 58.046575 | O8: =VLOOKUP(M8,Edad_Antigüedad!$M$2:$N$36,2) -> 30 | P8: SECUNDARIA | Q8: 0 | R8: 0 | S8: 0 | T8: 0 | U8: 0 | V8: 0 | W8: 0 | X8: 0 | Y8: 0 | Z8: 0 | AA8: 0
A9: CUARTOS FRIOS | B9: LLENADOR DE MOSTOS | C9: AM | D9: 32132025 | E9: SERGIO MIGUEL PARRA VAZQUEZ | F9: 32052981 | G9: JUAN JOSE MEJIA MONTOYA | H9: ANDAMOS CON TODO | I9: Llenador de mosto | J9: 1 | K9: 41806 | L9: 34606 | M9: =ROUND((($K$2-K9)/365),0) -> 12 | N9: =($K$2-L9)/365 -> 31.775342 | O9: =VLOOKUP(M9,Edad_Antigüedad!$M$2:$N$36,2) -> 24 | P9: PREPARATORIA | Q9: 0 | R9: 0 | S9: 0 | T9: 0 | U9: 0 | V9: 1 | W9: 1 | X9: 0 | Y9: 0 | Z9: 0 | AA9: 0
A10: CUARTOS FRIOS | B10: VACIADOR DE GOBIERNO | C10: AM | D10: 32045134 | E10: PEDRO MALDONADO MARQUEZ | F10: 32052981 | G10: JUAN JOSE MEJIA MONTOYA | H10: ANDAMOS CON TODO | I10: Vaciador de gobierno | J10: 1 | K10: 36811 | L10: 27415 | M10: =ROUND((($K$2-K10)/365),0) -> 26 | N10: =($K$2-L10)/365 -> 51.476712 | O10: =VLOOKUP(M10,Edad_Antigüedad!$M$2:$N$36,2) -> 30 | P10: SECUNDARIA | Q10: 0 | R10: 0 | S10: 0 | T10: 0 | U10: 0 | V10: 0 | W10: 1 | X10: 1 | Y10: 0 | Z10: 0 | AA10: 0
A11: CUARTOS FRIOS | B11: BOMBERO DE LEVADURA | C11: AM | D11: 32197863 | E11: CESAR RODRIGUEZ BANDA | F11: 32052981 | G11: JUAN JOSE MEJIA MONTOYA | H11: ANDAMOS CON TODO | I11: QUAS | J11: 1 | K11: 44057 | L11: 34189 | M11: =ROUND((($K$2-K11)/365),0) -> 6 | N11: =($K$2-L11)/365 -> 32.917808 | O11: =VLOOKUP(M11,Edad_Antigüedad!$M$2:$N$36,2) -> 22 | P11: SECUNDARIA | Q11: 0 | R11: 0 | S11: 0 | T11: 0 | U11: 0 | V11: 1 | W11: 1 | X11: 0 | Y11: 0 | Z11: 0 | AA11: 0
A12: CUARTOS FRIOS | B12: OPERADOR DE PLATOS | C12: AM | D12: 32197834 | E12: LUIS ADOLFO MALDONADO DOMINGUEZ | F12: 32052981 | G12: JUAN JOSE MEJIA MONTOYA | H12: ANDAMOS CON TODO | I12: Platos | J12: 1 | K12: 44428 | L12: 34371 | M12: =ROUND((($K$2-K12)/365),0) -> 5 | N12: =($K$2-L12)/365 -> 32.419178 | O12: =VLOOKUP(M12,Edad_Antigüedad!$M$2:$N$36,2) -> 20 | P12: PREPARATORIA | Q12: 0 | R12: 0 | S12: 0 | T12: 0 | U12: 1 | V12: 0 | W12: 0 | X12: 0 | Y12: 0 | Z12: 0 | AA12: 0
A13: CUARTOS FRIOS | B13: QUAS | C13: AM | D13: 32173446 | E13: JOSE EDUARDO ALVARADO CEBALLOS | F13: 32052981 | G13: JUAN JOSE MEJIA MONTOYA | H13: ANDAMOS CON TODO | I13: QUAs | J13: 1 | K13: 43434 | L13: 36016 | M13: =ROUND((($K$2-K13)/365),0) -> 8 | N13: =($K$2-L13)/365 -> 27.912329 | O13: =VLOOKUP(M13,Edad_Antigüedad!$M$2:$N$36,2) -> 22 | P13: LICENCIATURA | Q13: 0 | R13: 0 | S13: 0 | T13: 0 | U13: 0 | V13: 1 | W13: 1 | X13: 1 | Y13: 0 | Z13: 0 | AA13: 0
A14: CUARTOS FRIOS | B14: TECNICO DE ELABORACION | C14: 9 | D14: 32045116 | E14: JOSE LEANDRO MARTINEZ SANDOVAL | F14: 32052981 | G14: JUAN JOSE MEJIA MONTOYA | H14: ANDAMOS CON TODO | I14: Técnico de elaboración | J14: 1 | K14: 36801 | L14: 28061 | M14: =ROUND((($K$2-K14)/365),0) -> 26 | N14: =($K$2-L14)/365 -> 49.706849 | O14: =VLOOKUP(M14,Edad_Antigüedad!$M$2:$N$36,2) -> 30 | P14: LICENCIATURA | Q14: 0 | R14: 0 | S14: 0 | T14: 0 | U14: 0 | V14: 0 | W14: 1 | X14: 1 | Y14: 0 | Z14: 0 | AA14: 0 | AB14: 0 | AC14: 0 | AD14: 0 | AE14: 0 | AF14: 0 | AG14: 0 | AH14: 0
A15: CUARTOS FRIOS | B15: VACIADOR DE GOBIERNO | C15: AM | D15: 32149607 | E15: JORGE ALBERTO ORTIZ HERNANDEZ | F15: 32052981 | G15: JUAN JOSE MEJIA MONTOYA | H15: ANDAMOS CON TODO | I15: Vaciador de gobierno | J15: 1 | K15: 42527 | L15: 35079 | M15: =ROUND((($K$2-K15)/365),0) -> 10 | N15: =($K$2-L15)/365 -> 30.479452 | O15: =VLOOKUP(M15,Edad_Antigüedad!$M$2:$N$36,2) -> 22 | P15: SECUNDARIA | Q15: 0 | R15: 0 | S15: 0 | T15: 0 | U15: 0 | V15: 0 | W15: 1 | X15: 1 | Y15: 0 | Z15: 0 | AA15: 0
A16: CUARTOS FRIOS | B16: BOMBERO DE CERVEZA | C16: AM | D16: 32043880 | E16: JAIME CID VEYNA | F16: 32052981 | G16: JUAN JOSE MEJIA MONTOYA | H16: ANDAMOS CON TODO | I16: Bombero de cerveza | J16: 1 | K16: 35352 | L16: 25124 | M16: =ROUND((($K$2-K16)/365),0) -> 30 | N16: =($K$2-L16)/365 -> 57.753425 | O16: =VLOOKUP(M16,Edad_Antigüedad!$M$2:$N$36,2) -> 30 | P16: SECUNDARIA | Q16: 0 | R16: 0 | S16: 0 | T16: 0 | U16: 0 | V16: 1 | W16: 0 | X16: 0 | Y16: 0 | Z16: 0 | AA16: 0
A17: CUARTOS FRIOS | B17: TECNICO DE ELABORACION | C17: 9 | D17: 32045139 | E17: RICARDO ESPARZA DOMINGUEZ | F17: 32052981 | G17: JUAN JOSE MEJIA MONTOYA | H17: ANDAMOS CON TODO | I17: Técnico de elaboración | J17: 3 | K17: 36815 | L17: 27396 | M17: =ROUND((($K$2-K17)/365),0) -> 26 | N17: =($K$2-L17)/365 -> 51.528767 | O17: =VLOOKUP(M17,Edad_Antigüedad!$M$2:$N$36,2) -> 30 | P17: LICENCIATURA | Q17: 0 | R17: 0 | S17: 0 | T17: 0 | U17: 0 | V17: 0 | W17: 1 | X17: 1 | Y17: 0 | Z17: 1 | AA17: 0 | AB17: 0 | AC17: 0 | AD17: 0 | AE17: 0 | AF17: 0 | AG17: 0 | AH17: 0
A18: CUARTOS FRIOS | B18: LLENADOR DE MOSTOS | C18: AM | D18: 32044036 | E18: VICTOR SOTO LIZARDO | F18: 32052981 | G18: JUAN JOSE MEJIA MONTOYA | H18: ANDAMOS CON TODO | I18: Llenador de mosto | J18: 1 | K18: 35502 | L18: 28098 | M18: =ROUND((($K$2-K18)/365),0) -> 29 | N18: =($K$2-L18)/365 -> 49.605479 | O18: =VLOOKUP(M18,Edad_Antigüedad!$M$2:$N$36,2) -> 30 | P18: SECUNDARIA | Q18: 0 | R18: 0 | S18: 0 | T18: 0 | U18: 0 | V18: 1 | W18: 0 | X18: 0 | Y18: 0 | Z18: 0 | AA18: 0
A19: CUARTOS FRIOS | B19: TECNICO DE ELABORACION | C19: 9 | D19: 32143106 | E19: VICTOR HUGO ZAPATA DOMINGUEZ | F19: 32052981 | G19: JUAN JOSE MEJIA MONTOYA | H19: ANDAMOS CON TODO | I19: Técnico de elaboración | J19: 1 | K19: 42310 | L19: 32332 | M19: =ROUND((($K$2-K19)/365),0) -> 11 | N19: =($K$2-L19)/365 -> 38.005479 | O19: =VLOOKUP(M19,Edad_Antigüedad!$M$2:$N$36,2) -> 24 | P19: LICENCIATURA | Q19: 0 | R19: 0 | S19: 0 | T19: 0 | U19: 0 | V19: 0 | W19: 0 | X19: 1 | Y19: 0 | Z19: 1 | AA19: 1 | AB19: 0 | AC19: 0 | AD19: 0 | AE19: 0 | AF19: 0 | AG19: 0 | AH19: 0
A20: CUARTOS FRIOS | B20: VACIADOR DE GOBIERNO | C20: AM | D20: 32043886 | E20: RAFAEL CHAVEZ REVELES | F20: 32044049 | G20: RAUL DAVID CORTES ALANIZ | H20: BRAVOS DEL FRIO | I20: Vaciador de gobierno | J20: 1 | K20: 35359 | L20: 27728 | M20: =ROUND((($K$2-K20)/365),0) -> 30 | N20: =($K$2-L20)/365 -> 50.619178 | O20: =VLOOKUP(M20,Edad_Antigüedad!$M$2:$N$36,2) -> 30 | P20: SECUNDARIA | Q20: 0 | R20: 0 | S20: 0 | T20: 0 | U20: 0 | V20: 0 | W20: 1 | X20: 1 | Y20: 0 | Z20: 0 | AA20: 0
A21: CUARTOS FRIOS | B21: LLENADOR DE GOBIERNO | C21: AM | D21: 32043891 | E21: ARMANDO RAYZOLA ROLDAN | F21: 32044049 | G21: RAUL DAVID CORTES ALANIZ | H21: BRAVOS DEL FRIO | I21: Llenador de gobierno | J21: 1 | K21: 35366 | L21: 26219 | M21: =ROUND((($K$2-K21)/365),0) -> 30 | N21: =($K$2-L21)/365 -> 54.753425 | O21: =VLOOKUP(M21,Edad_Antigüedad!$M$2:$N$36,2) -> 30 | P21: SECUNDARIA | Q21: 0 | R21: 0 | S21: 0 | T21: 0 | U21: 0 | V21: 0 | W21: 0 | X21: 0 | Y21: 0 | Z21: 0 | AA21: 0
A22: CUARTOS FRIOS | B22: SUPERVISOR DE CUARTOS FRIOS | C22: 7 | D22: 32044049 | E22: RAUL DAVID CORTES ALANIZ | F22: 32045961 | G22: JAIME ALEJANDRO LAGUNAS CARRERA | H22: BRAVOS DEL FRIO | I22: LIDER DE TURNO | J22: 2 | K22: 35520 | L22: 26662 | M22: =ROUND((($K$2-K22)/365),0) -> 29 | N22: =($K$2-L22)/365 -> 53.539726 | O22: =VLOOKUP(M22,Edad_Antigüedad!$M$2:$N$36,2) -> 30 | P22: LICENCIATURA | Q22: 0 | R22: 0 | S22: 0 | T22: 0 | U22: 1 | V22: 1 | W22: 1 | X22: 1 | Y22: 1 | Z22: 1 | AA22: 0 | AB22: 0 | AC22: 0 | AD22: 0 | AE22: 0 | AF22: 0 | AG22: 0 | AH22: 0
A23: CUARTOS FRIOS | B23: TECNICO DE ELABORACION | C23: 9 | D23: 32044235 | E23: JESUS EDUARDO BRICEÑO MONTELONGO | F23: 32044049 | G23: RAUL DAVID CORTES ALANIZ | H23: BRAVOS DEL FRIO | I23: Técnico de elaboración | J23: 1 | K23: 35734 | L23: 25891 | M23: =ROUND((($K$2-K23)/365),0) -> 29 | N23: =($K$2-L23)/365 -> 55.652055 | O23: =VLOOKUP(M23,Edad_Antigüedad!$M$2:$N$36,2) -> 30 | P23: LICENCIATURA | Q23: 0 | R23: 0 | S23: 0 | T23: 0 | U23: 0 | V23: 0 | W23: 1 | X23: 1 | Y23: 0 | Z23: 0 | AA23: 0 | AB23: 0 | AC23: 0 | AD23: 0 | AE23: 0 | AF23: 0 | AG23: 0 | AH23: 0
A24: CUARTOS FRIOS | B24: BOMBERO DE LEVADURA | C24: AM | D24: 32044514 | E24: LUIS MANUEL DOMINGUEZ GARCIA | F24: 32044049 | G24: RAUL DAVID CORTES ALANIZ | H24: BRAVOS DEL FRIO | I24: Bombero de levadura | J24: 1 | K24: 36136 | L24: 26895 | M24: =ROUND((($K$2-K24)/365),0) -> 28 | N24: =($K$2-L24)/365 -> 52.90137 | O24: =VLOOKUP(M24,Edad_Antigüedad!$M$2:$N$36,2) -> 30 | P24: SECUNDARIA | Q24: 0 | R24: 0 | S24: 0 | T24: 0 | U24: 0 | V24: 1 | W24: 0 | X24: 0 | Y24: 0 | Z24: 0 | AA24: 0
A25: CUARTOS FRIOS | B25: BOMBERO DE CERVEZA | C25: AM | D25: 32044751 | E25: JUAN MANUEL HUERTA DE LA ROSA | F25: 32044049 | G25: RAUL DAVID CORTES ALANIZ | H25: BRAVOS DEL FRIO | I25: Bombero de cerveza | J25: 1 | K25: 36343 | L25: 29759 | M25: =ROUND((($K$2-K25)/365),0) -> 27 | N25: =($K$2-L25)/365 -> 45.054795 | O25: =VLOOKUP(M25,Edad_Antigüedad!$M$2:$N$36,2) -> 30 | P25: SECUNDARIA | Q25: 0 | R25: 0 | S25: 0 | T25: 0 | U25: 0 | V25: 1 | W25: 0 | X25: 0 | Y25: 0 | Z25: 0 | AA25: 0
A26: CUARTOS FRIOS | B26: LLENADOR DE MOSTOS | C26: AM | D26: 32044760 | E26: MAURICIO ARELLANO TREJO | F26: 32044049 | G26: RAUL DAVID CORTES ALANIZ | H26: BRAVOS DEL FRIO | I26: Llenador de mosto | J26: 1 | K26: 36351 | L26: 25328 | M26: =ROUND((($K$2-K26)/365),0) -> 27 | N26: =($K$2-L26)/365 -> 57.194521 | O26: =VLOOKUP(M26,Edad_Antigüedad!$M$2:$N$36,2) -> 30 | P26: SECUNDARIA | Q26: 0 | R26: 0 | S26: 0 | T26: 0 | U26: 0 | V26: 1 | W26: 0 | X26: 0 | Y26: 0 | Z26: 0 | AA26: 0
A27: CUARTOS FRIOS | B27: LLENADOR DE MOSTOS | C27: AM | D27: 32044771 | E27: RAFAEL MARTINEZ MARES | F27: 32044049 | G27: RAUL DAVID CORTES ALANIZ | H27: BRAVOS DEL FRIO | I27: Llenador de mosto | J27: 1 | K27: 36368 | L27: 28409 | M27: =ROUND((($K$2-K27)/365),0) -> 27 | N27: =($K$2-L27)/365 -> 48.753425 | O27: =VLOOKUP(M27,Edad_Antigüedad!$M$2:$N$36,2) -> 30 | P27: SECUNDARIA | Q27: 0 | R27: 0 | S27: 0 | T27: 0 | U27: 0 | V27: 1 | W27: 0 | X27: 0 | Y27: 0 | Z27: 0 | AA27: 0
A28: CUARTOS FRIOS | B28: LLENADOR DE GOBIERNO | C28: AM | D28: 32045574 | E28: PEDRO PALOS JARA | F28: 32044049 | G28: RAUL DAVID CORTES ALANIZ | H28: BRAVOS DEL FRIO | I28: Llenador de gobierno | J28: 1 | K28: 37298 | L28: 27234 | M28: =ROUND((($K$2-K28)/365),0) -> 24 | N28: =($K$2-L28)/365 -> 51.972603 | O28: =VLOOKUP(M28,Edad_Antigüedad!$M$2:$N$36,2) -> 28 | P28: SECUNDARIA | Q28: 0 | R28: 0 | S28: 0 | T28: 0 | U28: 0 | V28: 0 | W28: 0 | X28: 0 | Y28: 0 | Z28: 0 | AA28: 0
A29: CUARTOS FRIOS | B29: VACIADOR DE GOBIERNO | C29: AM | D29: 32111307 | E29: FRANCISCO JAVIER VARELA RODRIGUEZ | F29: 32044049 | G29: RAUL DAVID CORTES ALANIZ | H29: BRAVOS DEL FRIO | I29: Vaciador de gobierno | J29: 1 | K29: 41092 | L29: 33262 | M29: =ROUND((($K$2-K29)/365),0) -> 14 | N29: =($K$2-L29)/365 -> 35.457534 | O29: =VLOOKUP(M29,Edad_Antigüedad!$M$2:$N$36,2) -> 24 | P29: PREPARATORIA | Q29: 0 | R29: 0 | S29: 0 | T29: 0 | U29: 0 | V29: 0 | W29: 1 | X29: 1 | Y29: 0 | Z29: 0 | AA29: 0
A30: CUARTOS FRIOS | B30: MANEJO DE TIERRAS FILTRANTES | C30: AM | D30: 32142953 | E30: GERMAN RUEDAS SANCHEZ | F30: 32044049 | G30: RAUL DAVID CORTES ALANIZ | H30: BRAVOS DEL FRIO | I30: Manejo de tierras filtrantes | J30: 1 | K30: 42303 | L30: 31740 | M30: =ROUND((($K$2-K30)/365),0) -> 11 | N30: =($K$2-L30)/365 -> 39.627397 | O30: =VLOOKUP(M30,Edad_Antigüedad!$M$2:$N$36,2) -> 24 | P30: SECUNDARIA | Q30: 0 | R30: 0 | S30: 0 | T30: 0 | U30: 0 | V30: 0 | W30: 1 | X30: 1 | Y30: 0 | Z30: 0 | AA30: 0
A31: CUARTOS FRIOS | B31: TECNICO DE ELABORACION | C31: 9 | D31: 32146003 | E31: LUIS FERNANDO ZAPATA CARDONA | F31: 32044049 | G31: RAUL DAVID CORTES ALANIZ | H31: BRAVOS DEL FRIO | I31: Técnico de elaboración | J31: 2 | K31: 42402 | L31: 35454 | M31: =ROUND((($K$2-K31)/365),0) -> 10 | N31: =($K$2-L31)/365 -> 29.452055 | O31: =VLOOKUP(M31,Edad_Antigüedad!$M$2:$N$36,2) -> 22 | P31: LICENCIATURA | Q31: 0 | R31: 0 | S31: 0 | T31: 0 | U31: 1 | V31: 1 | W31: 1 | X31: 1 | Y31: 0 | Z31: 0 | AA31: 0 | AB31: 0 | AC31: 0 | AD31: 0 | AE31: 0 | AF31: 0 | AG31: 0 | AH31: 0
A32: CUARTOS FRIOS | B32: TECNICO DE ELABORACION | C32: 9 | D32: 32224377 | E32: CARLOS EDUARDO ORNEDO ESQUEDA | F32: 32044049 | G32: RAUL DAVID CORTES ALANIZ | H32: BRAVOS DEL FRIO | I32: Técnico de elaboración | J32: 2 | K32: 45231 | L32: 36134 | M32: =ROUND((($K$2-K32)/365),0) -> 3 | N32: =($K$2-L32)/365 -> 27.589041 | O32: =VLOOKUP(M32,Edad_Antigüedad!$M$2:$N$36,2) -> 16 | P32: LICENCIATURA | Q32: 0 | R32: 0 | S32: 0 | T32: 0 | U32: 0 | V32: 0 | W32: 0 | X32: 1 | Y32: 0 | Z32: 0 | AA32: 0 | AB32: 0 | AC32: 0 | AD32: 0 | AE32: 0 | AF32: 0 | AG32: 0 | AH32: 0
A33: CUARTOS FRIOS | B33: MANEJO DE TIERRAS FILTRANTES | C33: AM | D33: 32197833 | E33: JORGE LUIS RODRIGUEZ BERMUDEZ | F33: 32044049 | G33: RAUL DAVID CORTES ALANIZ | H33: BRAVOS DEL FRIO | I33: Bombero de cerveza | J33: 1 | K33: 44428 | L33: 35543 | M33: =ROUND((($K$2-K33)/365),0) -> 5 | N33: =($K$2-L33)/365 -> 29.208219 | O33: =VLOOKUP(M33,Edad_Antigüedad!$M$2:$N$36,2) -> 20 | P33: PREPARATORIA | Q33: 0 | R33: 0 | S33: 0 | T33: 0 | U33: 0 | V33: 0 | W33: 1 | X33: 0 | Y33: 0 | Z33: 0 | AA33: 0
A34: CUARTOS FRIOS | B34: MANEJO DE TIERRAS FILTRANTES | C34: AM | D34: 32209921 | E34: OSCAR EDUARDO VALDEZ MUÑOZ | F34: 32044049 | G34: RAUL DAVID CORTES ALANIZ | H34: BRAVOS DEL FRIO | I34: Platos | J34: 1 | K34: 44687 | L34: 36501 | M34: =ROUND((($K$2-K34)/365),0) -> 4 | N34: =($K$2-L34)/365 -> 26.583562 | O34: =VLOOKUP(M34,Edad_Antigüedad!$M$2:$N$36,2) -> 18 | P34: PREPARATORIA | Q34: 0 | R34: 0 | S34: 0 | T34: 0 | U34: 0 | V34: 0 | W34: 1 | X34: 0 | Y34: 0 | Z34: 0 | AA34: 0
A35: CUARTOS FRIOS | B35: TECNICO DE ELABORACION | C35: 9 | D35: 32233327 | E35: ISAÍ SOLOZANO HUARACHA | F35: 32044049 | G35: RAUL DAVID CORTES ALANIZ | H35: BRAVOS DEL FRIO | I35: Técnico de elaboración | J35: 1 | K35: 45705 | L35: 36793 | M35: =ROUND((($K$2-K35)/365),0) -> 1 | N35: =($K$2-L35)/365 -> 25.783562 | O35: =VLOOKUP(M35,Edad_Antigüedad!$M$2:$N$36,2) -> 12 | P35: LICENCIATURA | Q35: 0 | R35: 0 | S35: 0 | T35: 0 | U35: 0 | V35: 1 | W35: 0 | X35: 0 | Y35: 0 | Z35: 0 | AA35: 0
A36: COCIMIENTOS | B36: SUPERVISOR DE COCIMIENTOS | C36: 7 | D36: 32045014 | E36: J JESUS ALVARADO TENORIO | F36: 32132858 | G36: CLAUDIA ALEXANDRA ALVAREZ BARBA | H36: BREWMAN | I36: RELEVO DE VACACIONES | J36: 1 | K36: 36706 | L36: 27693 | M36: =ROUND((($K$2-K36)/365),0) -> 26 | N36: =($K$2-L36)/365 -> 50.715068 | O36: =VLOOKUP(M36,Edad_Antigüedad!$M$2:$N$36,2) -> 30 | P36: LICENCIATURA | R36: 1 | S36: 1 | T36: 1 | U36: 1 | V36: 0 | W36: 0 | X36: 0 | Y36: 0 | Z36: 0 | AA36: 0 | AB36: 0 | AC36: 0 | AD36: 0 | AE36: 0 | AF36: 0 | AG36: 0 | AH36: 0 | AI36: 0 | AJ36: 0 | AK36: 0 | AL36: 0 | AM36: 0 | AN36: 0 | AO36: 0
A37: CUARTOS FRIOS | B37: SUPERVISOR DE CUARTOS FRIOS | C37: 7 | D37: 32046063 | E37: TOPILTZIN TONATIUH I CURIEL CABRAL | F37: 32045961 | G37: JAIME ALEJANDRO LAGUNAS CARRERA | H37: BREWMAN | I37: RELEVO DE VACACIONES | J37: 1 | K37: 38201 | L37: 29670 | M37: =ROUND((($K$2-K37)/365),0) -> 22 | N37: =($K$2-L37)/365 -> 45.29863 | O37: =VLOOKUP(M37,Edad_Antigüedad!$M$2:$N$36,2) -> 28 | P37: LICENCIATURA | Q37: 1 | R37: 0 | S37: 0 | T37: 0 | U37: 1 | V37: 1 | W37: 1 | X37: 1 | Y37: 1 | Z37: 0 | AA37: 1 | AB37: 0 | AC37: 0 | AD37: 0 | AE37: 0 | AF37: 0 | AG37: 0 | AH37: 0
A38: CUARTOS FRIOS | B38: SUPERVISOR DE CUARTOS FRIOS | C38: 7 | D38: 32052750 | E38: OSCAR GUILLERMO MEJIA GARCIA | F38: 32132858 | G38: CLAUDIA ALEXANDRA ALVAREZ BARBA | H38: BREWMAN | I38: SUPERVISOR PROPAGACION | J38: 2 | K38: 38903 | L38: 28306 | M38: =ROUND((($K$2-K38)/365),0) -> 20 | N38: =($K$2-L38)/365 -> 49.035616 | O38: =VLOOKUP(M38,Edad_Antigüedad!$M$2:$N$36,2) -> 26 | P38: LICENCIATURA | Q38: 0 | R38: 0 | S38: 0 | T38: 0 | U38: 1 | V38: 1 | W38: 0 | X38: 0 | Y38: 0 | Z38: 0 | AA38: 0 | AB38: 0 | AC38: 0 | AD38: 0 | AE38: 0 | AF38: 0 | AG38: 0 | AH38: 0
A39: CUARTOS FRIOS | B39: INGENIERO EN PROCESOS | C39: 7 | D39: 32146683 | E39: OSCAR MANUEL GONZALEZ BOTELLO | F39: 32045961 | G39: AXEL GUILLEN RAMÍREZ | H39: BREWMAN | I39: INGENIERO EN PROCESO | J39: 2 | K39: 43907 | L39: 35312 | M39: =ROUND((($K$2-K39)/365),0) -> 6 | N39: =($K$2-L39)/365 -> 29.841096 | O39: =VLOOKUP(M39,Edad_Antigüedad!$M$2:$N$36,2) -> 22 | P39: LICENCIATURA | Q39: 0 | R39: 0 | S39: 0 | T39: 0 | U39: 0 | V39: 0 | W39: 0 | X39: 0 | Y39: 0 | Z39: 0 | AA39: 0 | AB39: 0 | AC39: 0 | AD39: 1 | AE39: 1 | AF39: 0 | AG39: 0 | AH39: 0
A40: COCIMIENTOS | B40: INGENIERO EN PROCESOS | C40: 7 | D40: 32044914 | E40: ADRIAN DIAZ MARRUFO | F40: 32052556 | G40: AXEL GUILLEN RAMÍREZ | H40: BREWMAN | I40: INGENIERO EN PROCESO | J40: 2 | K40: 36743 | L40: 26853 | M40: =ROUND((($K$2-K40)/365),0) -> 26 | N40: =($K$2-L40)/365 -> 53.016438 | O40: =VLOOKUP(M40,Edad_Antigüedad!$M$2:$N$36,2) -> 30 | P40: INGENIERIA | Q40: SIEBEL | R40: 0 | S40: 0 | T40: 0 | U40: 0 | V40: 0 | W40: 0 | X40: 0 | Y40: 0 | Z40: 0 | AA40: 0 | AB40: 0 | AC40: 0 | AD40: 0 | AE40: 0 | AF40: 0 | AG40: 0 | AH40: 0 | AI40: 0 | AJ40: 0 | AK40: 0 | AL40: 0 | AM40: 0 | AN40: 0 | AO40: 0
...
